2023-09-10 10:08:30,952 - INFO - starting
2023-09-10 10:08:30,957 - INFO - Inserting to Order submit
2023-09-10 10:08:30,957 - INFO - checking if table exist!!...
2023-09-10 10:08:30,998 - INFO - session closed
2023-09-10 10:08:30,999 - INFO - checking if table exist!!...
2023-09-10 10:08:31,017 - INFO - session closed
2023-09-10 10:08:31,017 - INFO - corresponding record found
2023-09-10 10:08:31,018 - INFO - checking if table exist!!...
2023-09-10 10:08:31,039 - ERROR - issue with query:(pymysql.err.IntegrityError) (1062, "Duplicate entry '36141bb3a7ccccb7c733e7bff6b697abe84da8c6-ghghflfgkkdrk90v0bjhjol' for key 'tbl_payment_metadata_producer.PRIMARY'")
[SQL: INSERT INTO external.tbl_payment_metadata_producer VALUES ('ghsgdhsh7873673hwgikk', '36141bb3a7ccccb7c733e7bff6b697abe84da8c6', 'ghghflfgkkdrk90v0bjhjol', 'ghghghgvbbbbbbbbbbbbbbbll', 'hjhjrffffffffffff', 1, 571.42, 1694365711018458700);]
(Background on this error at: https://sqlalche.me/e/20/gkpj)
2023-09-10 10:08:31,039 - INFO - session closed
2023-09-10 10:08:31,039 - ERROR - Issue with Inset_to_order function.. 
2023-09-10 10:09:34,013 - INFO - starting
2023-09-10 10:09:34,020 - INFO - Inserting to Order submit
2023-09-10 10:09:34,020 - INFO - checking if table exist!!...
2023-09-10 10:09:34,042 - INFO - session closed
2023-09-10 10:09:34,043 - INFO - checking if table exist!!...
2023-09-10 10:09:34,096 - INFO - session closed
2023-09-10 10:09:34,096 - INFO - corresponding record found
2023-09-10 10:09:34,097 - INFO - checking if table exist!!...
2023-09-10 10:09:34,133 - INFO - row inserted!..
2023-09-10 10:09:34,152 - INFO - session closed
2023-09-10 10:09:34,152 - INFO - Pushing to kafka
2023-09-10 10:09:34,157 - INFO - <BrokerConnection node_id=bootstrap-0 host=34.125.48.86:9092 <connecting> [IPv4 ('34.125.48.86', 9092)]>: connecting to 34.125.48.86:9092 [('34.125.48.86', 9092) IPv4]
2023-09-10 10:09:34,160 - INFO - Probing node bootstrap-0 broker version
2023-09-10 10:09:34,383 - INFO - <BrokerConnection node_id=bootstrap-0 host=34.125.48.86:9092 <connecting> [IPv4 ('34.125.48.86', 9092)]>: Connection complete.
2023-09-10 10:09:34,723 - INFO - Broker version identified as 2.5.0
2023-09-10 10:09:34,724 - INFO - Set configuration api_version=(2, 5, 0) to skip auto check_version requests on startup
2023-09-10 10:09:34,958 - INFO - <BrokerConnection node_id=0 host=34.125.48.86:9092 <connecting> [IPv4 ('34.125.48.86', 9092)]>: connecting to 34.125.48.86:9092 [('34.125.48.86', 9092) IPv4]
2023-09-10 10:09:35,167 - INFO - <BrokerConnection node_id=0 host=34.125.48.86:9092 <connecting> [IPv4 ('34.125.48.86', 9092)]>: Connection complete.
2023-09-10 10:09:35,168 - INFO - <BrokerConnection node_id=bootstrap-0 host=34.125.48.86:9092 <connected> [IPv4 ('34.125.48.86', 9092)]>: Closing connection. 
2023-09-10 10:09:35,384 - INFO - Message delivered to topic:wt-topic-0 in Partition: 2 with Offset: 0
2023-09-10 10:09:35,384 - INFO - Closing the Kafka producer with 4294967.0 secs timeout.
2023-09-10 10:09:35,385 - INFO - <BrokerConnection node_id=0 host=34.125.48.86:9092 <connected> [IPv4 ('34.125.48.86', 9092)]>: Closing connection. 
2023-09-10 10:12:54,207 - INFO - starting
2023-09-10 10:12:54,212 - ERROR - 'pg_order_id'
2023-09-10 10:12:54,213 - ERROR - Exception on /send_to_kafka [POST]
Traceback (most recent call last):
  File "C:\Users\Admin\AppData\Local\Packages\PythonSoftwareFoundation.Python.3.7_qbz5n2kfra8p0\LocalCache\local-packages\Python37\site-packages\flask\app.py", line 2528, in wsgi_app
    response = self.full_dispatch_request()
  File "C:\Users\Admin\AppData\Local\Packages\PythonSoftwareFoundation.Python.3.7_qbz5n2kfra8p0\LocalCache\local-packages\Python37\site-packages\flask\app.py", line 1826, in full_dispatch_request
    return self.finalize_request(rv)
  File "C:\Users\Admin\AppData\Local\Packages\PythonSoftwareFoundation.Python.3.7_qbz5n2kfra8p0\LocalCache\local-packages\Python37\site-packages\flask\app.py", line 1845, in finalize_request
    response = self.make_response(rv)
  File "C:\Users\Admin\AppData\Local\Packages\PythonSoftwareFoundation.Python.3.7_qbz5n2kfra8p0\LocalCache\local-packages\Python37\site-packages\apiflask\app.py", line 460, in make_response
    return super().make_response(rv)
  File "C:\Users\Admin\AppData\Local\Packages\PythonSoftwareFoundation.Python.3.7_qbz5n2kfra8p0\LocalCache\local-packages\Python37\site-packages\flask\app.py", line 2138, in make_response
    f"The view function for {request.endpoint!r} did not"
TypeError: The view function for 'send_to_kafka' did not return a valid response. The function either returned None or ended without a return statement.
2023-09-10 10:13:03,246 - INFO - starting
2023-09-10 10:13:03,251 - ERROR - 'pg_order_id'
2023-09-10 10:13:03,251 - ERROR - Exception on /send_to_kafka [POST]
Traceback (most recent call last):
  File "C:\Users\Admin\AppData\Local\Packages\PythonSoftwareFoundation.Python.3.7_qbz5n2kfra8p0\LocalCache\local-packages\Python37\site-packages\flask\app.py", line 2528, in wsgi_app
    response = self.full_dispatch_request()
  File "C:\Users\Admin\AppData\Local\Packages\PythonSoftwareFoundation.Python.3.7_qbz5n2kfra8p0\LocalCache\local-packages\Python37\site-packages\flask\app.py", line 1826, in full_dispatch_request
    return self.finalize_request(rv)
  File "C:\Users\Admin\AppData\Local\Packages\PythonSoftwareFoundation.Python.3.7_qbz5n2kfra8p0\LocalCache\local-packages\Python37\site-packages\flask\app.py", line 1845, in finalize_request
    response = self.make_response(rv)
  File "C:\Users\Admin\AppData\Local\Packages\PythonSoftwareFoundation.Python.3.7_qbz5n2kfra8p0\LocalCache\local-packages\Python37\site-packages\apiflask\app.py", line 460, in make_response
    return super().make_response(rv)
  File "C:\Users\Admin\AppData\Local\Packages\PythonSoftwareFoundation.Python.3.7_qbz5n2kfra8p0\LocalCache\local-packages\Python37\site-packages\flask\app.py", line 2138, in make_response
    f"The view function for {request.endpoint!r} did not"
TypeError: The view function for 'send_to_kafka' did not return a valid response. The function either returned None or ended without a return statement.
2023-09-10 10:14:38,697 - INFO - starting
2023-09-10 10:14:38,701 - ERROR - 'pg_order_id'
2023-09-10 10:14:38,701 - ERROR - Exception on /send_to_kafka [POST]
Traceback (most recent call last):
  File "C:\Users\Admin\AppData\Local\Packages\PythonSoftwareFoundation.Python.3.7_qbz5n2kfra8p0\LocalCache\local-packages\Python37\site-packages\flask\app.py", line 2528, in wsgi_app
    response = self.full_dispatch_request()
  File "C:\Users\Admin\AppData\Local\Packages\PythonSoftwareFoundation.Python.3.7_qbz5n2kfra8p0\LocalCache\local-packages\Python37\site-packages\flask\app.py", line 1826, in full_dispatch_request
    return self.finalize_request(rv)
  File "C:\Users\Admin\AppData\Local\Packages\PythonSoftwareFoundation.Python.3.7_qbz5n2kfra8p0\LocalCache\local-packages\Python37\site-packages\flask\app.py", line 1845, in finalize_request
    response = self.make_response(rv)
  File "C:\Users\Admin\AppData\Local\Packages\PythonSoftwareFoundation.Python.3.7_qbz5n2kfra8p0\LocalCache\local-packages\Python37\site-packages\apiflask\app.py", line 460, in make_response
    return super().make_response(rv)
  File "C:\Users\Admin\AppData\Local\Packages\PythonSoftwareFoundation.Python.3.7_qbz5n2kfra8p0\LocalCache\local-packages\Python37\site-packages\flask\app.py", line 2138, in make_response
    f"The view function for {request.endpoint!r} did not"
TypeError: The view function for 'send_to_kafka' did not return a valid response. The function either returned None or ended without a return statement.
